Workbook

Sheet Fact_Fulfillment_Static
A1: Fulfillment_ID | B1: Request_Date | C1: Fulfillment_Date | D1: Fulfillment_Status | E1: Days_To_Fulfill | F1: Item_Category | G1: Item_Type | H1: Qty_Req | I1: Qty_Full | J1: Partner_Org | K1: Client_Location | L1: Client_TypeID | M1: Delivery_Method | N1: Household_Size
A2: 1 | B2: 45762 | C2: 45767 | D2: Completed | E2: 5 | F2: Dining | G2: Dining Table | H2: 4 | I2: 4 | J2: Saco & Biddeford Savings | K2: Portland | L2: 1 | M2: Delivery | N2: 5
A3: 2 | B3: 45353 | C3: 45355 | D3: Completed | E3: 2 | F3: Household Essentials | G3: Bedding | H3: 3 | I3: 3 | J3: Rowe Ford Westbrook | K3: South Portland | L3: 2 | M3: Pickup | N3: 3
A4: 3 | B4: 45323 | C4: 45330 | D4: Completed | E4: 7 | F4: Bedroom | G4: Nightstand | H4: 4 | I4: 1 | J4: Developers Collaborative | K4: Biddeford | L4: 4 | M4: Delivery | N4: 6
A5: 4 | B5: 45786 | D5: Cancelled | F5: Living Room | G5: TV Stand | H5: 1 | J5: NewHeight Group | K5: Westbrook | L5: 4 | M5: Pickup | N5: 1
A6: 5 | B6: 45701 | C6: 45705 | D6: Completed | E6: 4 | F6: Living Room | G6: Sofa | H6: 1 | I6: 1 | J6: Shutterbugs 4 Charity | K6: Biddeford | L6: 6 | M6: Delivery | N6: 1
A7: 6 | B7: 45647 | D7: Cancelled | F7: Dining | G7: Dining Chair | H7: 3 | J7: Diversified | K7: Scarborough | L7: 5 | M7: Pickup | N7: 5
A8: 7 | B8: 45790 | C8: 45802 | D8: Completed | E8: 12 | F8: Dining | G8: Dining Table | H8: 2 | I8: 2 | J8: Jordan's Furniture | K8: Westbrook | L8: 6 | M8: Delivery | N8: 6
A9: 8 | B9: 45372 | C9: 45412 | D9: Completed | E9: 40 | F9: Household Essentials | G9: Lamps | H9: 1 | I9: 1 | J9: Developers Collaborative | K9: Portland | L9: 4 | M9: Delivery | N9: 4
A10: 9 | B10: 45815 | C10: 45860 | D10: Completed | E10: 45 | F10: Kitchen | G10: Dishes | H10: 4 | I10: 4 | J10: Maine Community Bank | K10: Portland | L10: 4 | M10: Delivery | N10: 1
A11: 10 | B11: 45812 | C11: 45822 | D11: Completed | E11: 10 | F11: Dining | G11: Dining Chair | H11: 1 | I11: 1 | J11: Diversified | K11: Scarborough | L11: 6 | M11: Delivery | N11: 2
A12: 11 | B12: 45348 | C12: 45354 | D12: Completed | E12: 6 | F12: Living Room | G12: Sofa | H12: 4 | I12: 2 | J12: Rowe Ford Westbrook | K12: Scarborough | L12: 1 | M12: Delivery | N12: 1
A13: 12 | B13: 45676 | C13: 45682 | D13: Completed | E13: 6 | F13: Office | G13: Desk | H13: 4 | I13: 3 | J13: EthosVont | K13: Portland | L13: 1 | M13: Delivery | N13: 5
A14: 13 | B14: 45487 | D14: Cancelled | F14: Household Essentials | G14: Rugs | H14: 2 | J14: Westbrook Housing | K14: Scarborough | L14: 3 | M14: Delivery | N14: 2
A15: 14 | B15: 45307 | C15: 45321 | D15: Completed | E15: 14 | F15: Kitchen | G15: Small Appliances | H15: 3 | I15: 2 | J15: Rowe Ford Westbrook | K15: South Portland | L15: 1 | M15: Delivery | N15: 3
A16: 15 | B16: 45324 | C16: 45335 | D16: Completed | E16: 11 | F16: Dining | G16: Dining Table | H16: 1 | I16: 1 | J16: Spiritual Workers | K16: Biddeford | L16: 1 | M16: Pickup | N16: 4
A17: 16 | B17: 45577 | C17: 45579 | D17: Completed | E17: 2 | F17: Household Essentials | G17: Bedding | H17: 1 | I17: 1 | J17: Maine Community Bank | K17: South Portland | L17: 2 | M17: Delivery | N17: 5
A18: 17 | B18: 45429 | D18: Pending | F18: Kitchen | G18: Dishes | H18: 4 | J18: EthosVont | K18: Westbrook | L18: 1 | M18: Pickup | N18: 3
A19: 18 | B19: 45686 | D19: Pending | F19: Household Essentials | G19: Bedding | H19: 1 | J19: Diversified | K19: Westbrook | L19: 1 | M19: Pickup | N19: 6
A20: 19 | B20: 45605 | C20: 45612 | D20: Completed | E20: 7 | F20: Kitchen | G20: Microwave | H20: 2 | I20: 2 | J20: EthosVont | K20: Westbrook | L20: 2 | M20: Pickup | N20: 1
A21: 20 | B21: 45679 | C21: 45693 | D21: Completed | E21: 14 | F21: Living Room | G21: Armchair | H21: 2 | I21: 2 | J21: GoGo Refill | K21: Biddeford | L21: 4 | M21: Delivery | N21: 2
A22: 21 | B22: 45725 | C22: 45728 | D22: Completed | E22: 3 | F22: Office | G22: Office Chair | H22: 3 | I22: 1 | J22: Spiritual Workers | K22: Biddeford | L22: 5 | M22: Delivery | N22: 2
A23: 22 | B23: 45490 | C23: 45496 | D23: Completed | E23: 6 | F23: Household Essentials | G23: Bedding | H23: 4 | I23: 2 | J23: EthosVont | K23: Biddeford | L23: 2 | M23: Delivery | N23: 2
A24: 23 | B24: 45391 | C24: 45392 | D24: Completed | E24: 1 | F24: Living Room | G24: Armchair | H24: 4 | I24: 2 | J24: Diversified | K24: Biddeford | L24: 4 | M24: Pickup | N24: 6
A25: 24 | B25: 45734 | C25: 45777 | D25: Completed | E25: 43 | F25: Living Room | G25: Armchair | H25: 4 | I25: 2 | J25: Portland Mattress Makers | K25: Westbrook | L25: 4 | M25: Delivery | N25: 2
A26: 25 | B26: 45368 | C26: 45373 | D26: Completed | E26: 5 | F26: Household Essentials | G26: Bedding | H26: 4 | I26: 1 | J26: Westbrook Housing | K26: South Portland | L26: 6 | M26: Delivery | N26: 3
A27: 26 | B27: 45501 | C27: 45527 | D27: Completed | E27: 26 | F27: Office | G27: Office Chair | H27: 1 | I27: 1 | J27: Portland Harbor Group Raymond James | K27: Scarborough | L27: 6 | M27: Delivery | N27: 1
A28: 27 | B28: 45495 | C28: 45523 | D28: Completed | E28: 28 | F28: Dining | G28: Dining Chair | H28: 3 | I28: 1 | J28: Westbrook Housing | K28: Scarborough | L28: 1 | M28: Pickup | N28: 4
A29: 28 | B29: 45397 | C29: 45404 | D29: Completed | E29: 7 | F29: Bedroom | G29: Bed Frame | H29: 1 | I29: 1 | J29: Shutterbugs 4 Charity | K29: Biddeford | L29: 4 | M29: Pickup | N29: 1
A30: 29 | B30: 45829 | C30: 45843 | D30: Completed | E30: 14 | F30: Household Essentials | G30: Lamps | H30: 1 | I30: 1 | J30: NewHeight Group | K30: Portland | L30: 3 | M30: Pickup | N30: 6
A31: 30 | B31: 45755 | C31: 45767 | D31: Completed | E31: 12 | F31: Bedroom | G31: Bed Frame | H31: 3 | I31: 3 | J31: Spiritual Workers | K31: Falmouth | L31: 4 | M31: Pickup | N31: 1
A32: 31 | B32: 45813 | C32: 45818 | D32: Completed | E32: 5 | F32: Bedroom | G32: Dresser | H32: 3 | I32: 2 | J32: Portland Harbor Group Raymond James | K32: Portland | L32: 2 | M32: Pickup | N32: 6
A33: 32 | B33: 45393 | D33: Pending | F33: Bedroom | G33: Nightstand | H33: 1 | J33: Systems Engineering | K33: Portland | L33: 5 | M33: Delivery | N33: 3
A34: 33 | B34: 45347 | C34: 45349 | D34: Completed | E34: 2 | F34: Household Essentials | G34: Rugs | H34: 3 | I34: 1 | J34: EthosVont | K34: Westbrook | L34: 6 | M34: Delivery | N34: 4
A35: 34 | B35: 45762 | C35: 45783 | D35: Completed | E35: 21 | F35: Office | G35: Desk | H35: 3 | I35: 3 | J35: Center for Real Estate Studies | K35: Portland | L35: 6 | M35: Delivery | N35: 3
A36: 35 | B36: 45814 | C36: 45838 | D36: Completed | E36: 24 | F36: Office | G36: Office Chair | H36: 3 | I36: 1 | J36: Rowe Ford Westbrook | K36: Biddeford | L36: 6 | M36: Delivery | N36: 5
A37: 36 | B37: 45527 | D37: Cancelled | F37: Household Essentials | G37: Rugs | H37: 1 | J37: Systems Engineering | K37: Westbrook | L37: 3 | M37: Delivery | N37: 4
A38: 37 | B38: 45426 | C38: 45429 | D38: Completed | E38: 3 | F38: Dining | G38: Dining Table | H38: 4 | I38: 1 | J38: Coffee By Design | K38: Falmouth | L38: 5 | M38: Pickup | N38: 5
A39: 38 | B39: 45493 | C39: 45500 | D39: Completed | E39: 7 | F39: Kitchen | G39: Dishes | H39: 1 | I39: 1 | J39: NewHeight Group | K39: Portland | L39: 1 | M39: Delivery | N39: 6
A40: 39 | B40: 45340 | C40: 45346 | D40: Completed | E40: 6 | F40: Living Room | G40: Sofa | H40: 2 | I40: 2 | J40: Diversified | K40: Westbrook | L40: 4 | M40: Pickup | N40: 2
...

Sheet Dim_Client_Information
A1: ClientTypeID | B1: ClientTypeName
A2: 1 | B2: Shelter
A3: 2 | B3: Veteran
A4: 3 | B4: Refugee / Immigrant
A5: 4 | B5: Formerly Homeless
A6: 5 | B6: Low-Income Family
A7: 6 | B7: Other

Sheet Dim_Partner_Organizations
A1: PartnerOrg | B1: PartnerType | C1: Town | D1: Region
A2: Westbrook Housing | B2: Housing Authority | C2: Westbrook | D2: Southern ME
A3: Keybank | B3: Corporate Partner | C3: Portland | D3: Southern ME
A4: Jordan's Furniture | B4: Corporate Donor | C4: Portland | D4: Southern ME
A5: Diversified | B5: Corporate Partner | C5: Portland | D5: Southern ME
A6: Shutterbugs 4 Charity | B6: Nonprofit | C6: Portland | D6: Southern ME
A7: Center for Real Estate Studies | B7: Education / Research | C7: Portland | D7: Southern ME
A8: Portland Mattress Makers | B8: Manufacturer / Donor | C8: Portland | D8: Southern ME
A9: Developers Collaborative | B9: Corporate Partner | C9: Portland | D9: Southern ME
A10: Rowe Ford Westbrook | B10: Corporate Donor | C10: Westbrook | D10: Southern ME
A11: GoGo Refill | B11: Small Business Partner | C11: Portland | D11: Southern ME
A12: NewHeight Group | B12: Corporate Partner | C12: Portland | D12: Southern ME
... A20: Systems Engineering | B20: Technology / Corporate Partner | C20: Portland | D20: Southern ME

Sheet Fact_Fulfillment
A1: Fulfillment_ID | B1: Request_Date | C1: Fulfillment_Date | D1: Fulfillment_Status | E1: Days_To_Fulfill | F1: Item_Category | G1: Item_Type | H1: Qty_Req | I1: Qty_Full | J1: Partner_Org | K1: Client_Location | L1: Client_TypeID | M1: Delivery_Method | N1: Household_Size
A2: =ROW()-1 -> 1 | B2: =DATE(2024,1,1)+RANDBETWEEN(0,540) -> 45657 | C2: =IF(RAND()<=0.8, IF(RANDBETWEEN(1,10)<=8, B2+RANDBETWEEN(1,14), B2+RANDBETWEEN(15,45) ), "") -> 45659 | D2: =IF(C2<>"","Completed", IF(RAND()<=0.7,"Pending","Cancelled")) -> Completed | E2: =IF(C2<>"", C2-B2, "") -> 2 | F2: {=INDEX(lists!F:F,RANDBETWEEN(1,6))} -> Dining | G2: {=IFS( F2="Bedroom",INDEX(lists!G:G,RANDBETWEEN(1,4)), F2="Living Room",INDEX(lists!H:H,RANDBETWEEN(1,4)), F2="Dining",INDEX(lists!I:I,RANDBETWEEN(1,2)), F2="Kitchen",INDEX(lists!J:J,RANDBETWEEN(1,4)), F2="Office",INDEX(lists!K:K,RANDBETWEEN(1,3)), F2="Household Essentials",INDEX(lists!L:L,RANDBETWEEN(1,3)) )} -> Dining Chair | H2: =RANDBETWEEN(1,4) -> 1 | I2: =IF(C2<>"", RANDBETWEEN(1,H2), "") -> 1 | J2: {=INDEX(lists!A:A,RANDBETWEEN(1,19))} -> Westbrook Housing | K2: {=INDEX(lists!N:N,RANDBETWEEN(1,6))} -> Biddeford | L2: =RANDBETWEEN(1,6) -> 3 | M2: {=INDEX(lists!O:O,RANDBETWEEN(1,2))} -> Pickup | N2: =RANDBETWEEN(1,6) -> 3
A3: =ROW()-1 -> 2 | B3: =DATE(2024,1,1)+RANDBETWEEN(0,540) -> 45647 | C3: =IF(RAND()<=0.8, IF(RANDBETWEEN(1,10)<=8, B3+RANDBETWEEN(1,14), B3+RANDBETWEEN(15,45) ), "") -> 45679 | D3: =IF(C3<>"","Completed", IF(RAND()<=0.7,"Pending","Cancelled")) -> Completed | E3: =IF(C3<>"", C3-B3, "") -> 32 | F3: {=INDEX(lists!F:F,RANDBETWEEN(1,6))} -> Bedroom | G3: {=IFS( F3="Bedroom",INDEX(lists!G:G,RANDBETWEEN(1,4)), F3="Living Room",INDEX(lists!H:H,RANDBETWEEN(1,4)), F3="Dining",INDEX(lists!I:I,RANDBETWEEN(1,2)), F3="Kitchen",INDEX(lists!J:J,RANDBETWEEN(1,4)), F3="Office",INDEX(lists!K:K,RANDBETWEEN(1,3)), F3="Household Essentials",INDEX(lists!L:L,RANDBETWEEN(1,3)) )} -> Bed Frame | H3: =RANDBETWEEN(1,4) -> 4 | I3: =IF(C3<>"", RANDBETWEEN(1,H3), "") -> 2 | J3: {=INDEX(lists!A:A,RANDBETWEEN(1,19))} -> NewHeight Group | K3: {=INDEX(lists!N:N,RANDBETWEEN(1,6))} -> Scarborough | L3: =RANDBETWEEN(1,6) -> 4 | M3: {=INDEX(lists!O:O,RANDBETWEEN(1,2))} -> Pickup | N3: =RANDBETWEEN(1,6) -> 1
A4: =ROW()-1 -> 3 | B4: =DATE(2024,1,1)+RANDBETWEEN(0,540) -> 45552 | C4: =IF(RAND()<=0.8, IF(RANDBETWEEN(1,10)<=8, B4+RANDBETWEEN(1,14), B4+RANDBETWEEN(15,45) ), "") -> 45554 | D4: =IF(C4<>"","Completed", IF(RAND()<=0.7,"Pending","Cancelled")) -> Completed | E4: =IF(C4<>"", C4-B4, "") -> 2 | F4: {=INDEX(lists!F:F,RANDBETWEEN(1,6))} -> Dining | G4: {=IFS( F4="Bedroom",INDEX(lists!G:G,RANDBETWEEN(1,4)), F4="Living Room",INDEX(lists!H:H,RANDBETWEEN(1,4)), F4="Dining",INDEX(lists!I:I,RANDBETWEEN(1,2)), F4="Kitchen",INDEX(lists!J:J,RANDBETWEEN(1,4)), F4="Office",INDEX(lists!K:K,RANDBETWEEN(1,3)), F4="Household Essentials",INDEX(lists!L:L,RANDBETWEEN(1,3)) )} -> Dining Table | H4: =RANDBETWEEN(1,4) -> 4 | I4: =IF(C4<>"", RANDBETWEEN(1,H4), "") -> 3 | J4: {=INDEX(lists!A:A,RANDBETWEEN(1,19))} -> Coffee By Design | K4: {=INDEX(lists!N:N,RANDBETWEEN(1,6))} -> Portland | L4: =RANDBETWEEN(1,6) -> 5 | M4: {=INDEX(lists!O:O,RANDBETWEEN(1,2))} -> Delivery | N4: =RANDBETWEEN(1,6) -> 4
A5: =ROW()-1 -> 4 | B5: =DATE(2024,1,1)+RANDBETWEEN(0,540) -> 45678 | C5: =IF(RAND()<=0.8, IF(RANDBETWEEN(1,10)<=8, B5+RANDBETWEEN(1,14), B5+RANDBETWEEN(15,45) ), "") -> 45692 | D5: =IF(C5<>"","Completed", IF(RAND()<=0.7,"Pending","Cancelled")) -> Completed | E5: =IF(C5<>"", C5-B5, "") -> 14 | F5: {=INDEX(lists!F:F,RANDBETWEEN(1,6))} -> Kitchen | G5: {=IFS( F5="Bedroom",INDEX(lists!G:G,RANDBETWEEN(1,4)), F5="Living Room",INDEX(lists!H:H,RANDBETWEEN(1,4)), F5="Dining",INDEX(lists!I:I,RANDBETWEEN(1,2)), F5="Kitchen",INDEX(lists!J:J,RANDBETWEEN(1,4)), F5="Office",INDEX(lists!K:K,RANDBETWEEN(1,3)), F5="Household Essentials",INDEX(lists!L:L,RANDBETWEEN(1,3)) )} -> Dishes | H5: =RANDBETWEEN(1,4) -> 1 | I5: =IF(C5<>"", RANDBETWEEN(1,H5), "") -> 1 | J5: {=INDEX(lists!A:A,RANDBETWEEN(1,19))} -> Spiritual Workers | K5: {=INDEX(lists!N:N,RANDBETWEEN(1,6))} -> Biddeford | L5: =RANDBETWEEN(1,6) -> 6 | M5: {=INDEX(lists!O:O,RANDBETWEEN(1,2))} -> Delivery | N5: =RANDBETWEEN(1,6) -> 4
A6: =ROW()-1 -> 5 | B6: =DATE(2024,1,1)+RANDBETWEEN(0,540) -> 45560 | C6: =IF(RAND()<=0.8, IF(RANDBETWEEN(1,10)<=8, B6+RANDBETWEEN(1,14), B6+RANDBETWEEN(15,45) ), "") -> 45564 | D6: =IF(C6<>"","Completed", IF(RAND()<=0.7,"Pending","Cancelled")) -> Completed | E6: =IF(C6<>"", C6-B6, "") -> 4 | F6: {=INDEX(lists!F:F,RANDBETWEEN(1,6))} -> Kitchen | G6: {=IFS( F6="Bedroom",INDEX(lists!G:G,RANDBETWEEN(1,4)), F6="Living Room",INDEX(lists!H:H,RANDBETWEEN(1,4)), F6="Dining",INDEX(lists!I:I,RANDBETWEEN(1,2)), F6="Kitchen",INDEX(lists!J:J,RANDBETWEEN(1,4)), F6="Office",INDEX(lists!K:K,RANDBETWEEN(1,3)), F6="Household Essentials",INDEX(lists!L:L,RANDBETWEEN(1,3)) )} -> Dishes | H6: =RANDBETWEEN(1,4) -> 2 | I6: =IF(C6<>"", RANDBETWEEN(1,H6), "") -> 1 | J6: {=INDEX(lists!A:A,RANDBETWEEN(1,19))} -> Shutterbugs 4 Charity | K6: {=INDEX(lists!N:N,RANDBETWEEN(1,6))} -> Scarborough | L6: =RANDBETWEEN(1,6) -> 4 | M6: {=INDEX(lists!O:O,RANDBETWEEN(1,2))} -> Pickup | N6: =RANDBETWEEN(1,6) -> 2
A7: =ROW()-1 -> 6 | B7: =DATE(2024,1,1)+RANDBETWEEN(0,540) -> 45345 | C7: =IF(RAND()<=0.8, IF(RANDBETWEEN(1,10)<=8, B7+RANDBETWEEN(1,14), B7+RANDBETWEEN(15,45) ), "") -> 45352 | D7: =IF(C7<>"","Completed", IF(RAND()<=0.7,"Pending","Cancelled")) -> Completed | E7: =IF(C7<>"", C7-B7, "") -> 7 | F7: {=INDEX(lists!F:F,RANDBETWEEN(1,6))} -> Dining | G7: {=IFS( F7="Bedroom",INDEX(lists!G:G,RANDBETWEEN(1,4)), F7="Living Room",INDEX(lists!H:H,RANDBETWEEN(1,4)), F7="Dining",INDEX(lists!I:I,RANDBETWEEN(1,2)), F7="Kitchen",INDEX(lists!J:J,RANDBETWEEN(1,4)), F7="Office",INDEX(lists!K:K,RANDBETWEEN(1,3)), F7="Household Essentials",INDEX(lists!L:L,RANDBETWEEN(1,3)) )} -> Dining Table | H7: =RANDBETWEEN(1,4) -> 4 | I7: =IF(C7<>"", RANDBETWEEN(1,H7), "") -> 3 | J7: {=INDEX(lists!A:A,RANDBETWEEN(1,19))} -> GoGo Refill | K7: {=INDEX(lists!N:N,RANDBETWEEN(1,6))} -> Scarborough | L7: =RANDBETWEEN(1,6) -> 6 | M7: {=INDEX(lists!O:O,RANDBETWEEN(1,2))} -> Delivery | N7: =RANDBETWEEN(1,6) -> 3
A8: =ROW()-1 -> 7 | B8: =DATE(2024,1,1)+RANDBETWEEN(0,540) -> 45580 | C8: =IF(RAND()<=0.8, IF(RANDBETWEEN(1,10)<=8, B8+RANDBETWEEN(1,14), B8+RANDBETWEEN(15,45) ), "") -> 45614 | D8: =IF(C8<>"","Completed", IF(RAND()<=0.7,"Pending","Cancelled")) -> Completed | E8: =IF(C8<>"", C8-B8, "") -> 34 | F8: {=INDEX(lists!F:F,RANDBETWEEN(1,6))} -> Dining | G8: {=IFS( F8="Bedroom",INDEX(lists!G:G,RANDBETWEEN(1,4)), F8="Living Room",INDEX(lists!H:H,RANDBETWEEN(1,4)), F8="Dining",INDEX(lists!I:I,RANDBETWEEN(1,2)), F8="Kitchen",INDEX(lists!J:J,RANDBETWEEN(1,4)), F8="Office",INDEX(lists!K:K,RANDBETWEEN(1,3)), F8="Household Essentials",INDEX(lists!L:L,RANDBETWEEN(1,3)) )} -> Dining Table | H8: =RANDBETWEEN(1,4) -> 3 | I8: =IF(C8<>"", RANDBETWEEN(1,H8), "") -> 2 | J8: {=INDEX(lists!A:A,RANDBETWEEN(1,19))} -> Keybank | K8: {=INDEX(lists!N:N,RANDBETWEEN(1,6))} -> Biddeford | L8: =RANDBETWEEN(1,6) -> 3 | M8: {=INDEX(lists!O:O,RANDBETWEEN(1,2))} -> Delivery | N8: =RANDBETWEEN(1,6) -> 1
A9: =ROW()-1 -> 8 | B9: =DATE(2024,1,1)+RANDBETWEEN(0,540) -> 45509 | C9: =IF(RAND()<=0.8, IF(RANDBETWEEN(1,10)<=8, B9+RANDBETWEEN(1,14), B9+RANDBETWEEN(15,45) ), "") -> 45545 | D9: =IF(C9<>"","Completed", IF(RAND()<=0.7,"Pending","Cancelled")) -> Completed | E9: =IF(C9<>"", C9-B9, "") -> 36 | F9: {=INDEX(lists!F:F,RANDBETWEEN(1,6))} -> Household Essentials | G9: {=IFS( F9="Bedroom",INDEX(lists!G:G,RANDBETWEEN(1,4)), F9="Living Room",INDEX(lists!H:H,RANDBETWEEN(1,4)), F9="Dining",INDEX(lists!I:I,RANDBETWEEN(1,2)), F9="Kitchen",INDEX(lists!J:J,RANDBETWEEN(1,4)), F9="Office",INDEX(lists!K:K,RANDBETWEEN(1,3)), F9="Household Essentials",INDEX(lists!L:L,RANDBETWEEN(1,3)) )} -> Rugs | H9: =RANDBETWEEN(1,4) -> 1 | I9: =IF(C9<>"", RANDBETWEEN(1,H9), "") -> 1 | J9: {=INDEX(lists!A:A,RANDBETWEEN(1,19))} -> EthosVont | K9: {=INDEX(lists!N:N,RANDBETWEEN(1,6))} -> South Portland | L9: =RANDBETWEEN(1,6) -> 5 | M9: {=INDEX(lists!O:O,RANDBETWEEN(1,2))} -> Delivery | N9: =RANDBETWEEN(1,6) -> 5
A10: =ROW()-1 -> 9 | B10: =DATE(2024,1,1)+RANDBETWEEN(0,540) -> 45522 | C10: =IF(RAND()<=0.8, IF(RANDBETWEEN(1,10)<=8, B10+RANDBETWEEN(1,14), B10+RANDBETWEEN(15,45) ), "") -> 45536 | D10: =IF(C10<>"","Completed", IF(RAND()<=0.7,"Pending","Cancelled")) -> Completed | E10: =IF(C10<>"", C10-B10, "") -> 14 | F10: {=INDEX(lists!F:F,RANDBETWEEN(1,6))} -> Bedroom | G10: {=IFS( F10="Bedroom",INDEX(lists!G:G,RANDBETWEEN(1,4)), F10="Living Room",INDEX(lists!H:H,RANDBETWEEN(1,4)), F10="Dining",INDEX(lists!I:I,RANDBETWEEN(1,2)), F10="Kitchen",INDEX(lists!J:J,RANDBETWEEN(1,4)), F10="Office",INDEX(lists!K:K,RANDBETWEEN(1,3)), F10="Household Essentials",INDEX(lists!L:L,RANDBETWEEN(1,3)) )} -> Mattress | H10: =RANDBETWEEN(1,4) -> 2 | I10: =IF(C10<>"", RANDBETWEEN(1,H10), "") -> 1 | J10: {=INDEX(lists!A:A,RANDBETWEEN(1,19))} -> J.B Brown and Sons | K10: {=INDEX(lists!N:N,RANDBETWEEN(1,6))} -> Falmouth | L10: =RANDBETWEEN(1,6) -> 3 | M10: {=INDEX(lists!O:O,RANDBETWEEN(1,2))} -> Delivery | N10: =RANDBETWEEN(1,6) -> 2
A11: =ROW()-1 -> 10 | B11: =DATE(2024,1,1)+RANDBETWEEN(0,540) -> 45579 | C11: =IF(RAND()<=0.8, IF(RANDBETWEEN(1,10)<=8, B11+RANDBETWEEN(1,14), B11+RANDBETWEEN(15,45) ), "") -> 45590 | D11: =IF(C11<>"","Completed", IF(RAND()<=0.7,"Pending","Cancelled")) -> Completed | E11: =IF(C11<>"", C11-B11, "") -> 11 | F11: {=INDEX(lists!F:F,RANDBETWEEN(1,6))} -> Kitchen | G11: {=IFS( F11="Bedroom",INDEX(lists!G:G,RANDBETWEEN(1,4)), F11="Living Room",INDEX(lists!H:H,RANDBETWEEN(1,4)), F11="Dining",INDEX(lists!I:I,RANDBETWEEN(1,2)), F11="Kitchen",INDEX(lists!J:J,RANDBETWEEN(1,4)), F11="Office",INDEX(lists!K:K,RANDBETWEEN(1,3)), F11="Household Essentials",INDEX(lists!L:L,RANDBETWEEN(1,3)) )} -> Microwave | H11: =RANDBETWEEN(1,4) -> 3 | I11: =IF(C11<>"", RANDBETWEEN(1,H11), "") -> 1 | J11: {=INDEX(lists!A:A,RANDBETWEEN(1,19))} -> Saco & Biddeford Savings | K11: {=INDEX(lists!N:N,RANDBETWEEN(1,6))} -> Portland | L11: =RANDBETWEEN(1,6) -> 2 | M11: {=INDEX(lists!O:O,RANDBETWEEN(1,2))} -> Delivery | N11: =RANDBETWEEN(1,6) -> 4
A12: =ROW()-1 -> 11 | B12: =DATE(2024,1,1)+RANDBETWEEN(0,540) -> 45355 | C12: =IF(RAND()<=0.8, IF(RANDBETWEEN(1,10)<=8, B12+RANDBETWEEN(1,14), B12+RANDBETWEEN(15,45) ), "") -> 45367 | D12: =IF(C12<>"","Completed", IF(RAND()<=0.7,"Pending","Cancelled")) -> Completed | E12: =IF(C12<>"", C12-B12, "") -> 12 | F12: {=INDEX(lists!F:F,RANDBETWEEN(1,6))} -> Bedroom | G12: {=IFS( F12="Bedroom",INDEX(lists!G:G,RANDBETWEEN(1,4)), F12="Living Room",INDEX(lists!H:H,RANDBETWEEN(1,4)), F12="Dining",INDEX(lists!I:I,RANDBETWEEN(1,2)), F12="Kitchen",INDEX(lists!J:J,RANDBETWEEN(1,4)), F12="Office",INDEX(lists!K:K,RANDBETWEEN(1,3)), F12="Household Essentials",INDEX(lists!L:L,RANDBETWEEN(1,3)) )} -> Mattress | H12: =RANDBETWEEN(1,4) -> 2 | I12: =IF(C12<>"", RANDBETWEEN(1,H12), "") -> 1 | J12: {=INDEX(lists!A:A,RANDBETWEEN(1,19))} -> Keybank | K12: {=INDEX(lists!N:N,RANDBETWEEN(1,6))} -> South Portland | L12: =RANDBETWEEN(1,6) -> 5 | M12: {=INDEX(lists!O:O,RANDBETWEEN(1,2))} -> Delivery | N12: =RANDBETWEEN(1,6) -> 5
A13: =ROW()-1 -> 12 | B13: =DATE(2024,1,1)+RANDBETWEEN(0,540) -> 45600 | C13: =IF(RAND()<=0.8, IF(RANDBETWEEN(1,10)<=8, B13+RANDBETWEEN(1,14), B13+RANDBETWEEN(15,45) ), "") -> 45631 | D13: =IF(C13<>"","Completed", IF(RAND()<=0.7,"Pending","Cancelled")) -> Completed | E13: =IF(C13<>"", C13-B13, "") -> 31 | F13: {=INDEX(lists!F:F,RANDBETWEEN(1,6))} -> Kitchen | G13: {=IFS( F13="Bedroom",INDEX(lists!G:G,RANDBETWEEN(1,4)), F13="Living Room",INDEX(lists!H:H,RANDBETWEEN(1,4)), F13="Dining",INDEX(lists!I:I,RANDBETWEEN(1,2)), F13="Kitchen",INDEX(lists!J:J,RANDBETWEEN(1,4)), F13="Office",INDEX(lists!K:K,RANDBETWEEN(1,3)), F13="Household Essentials",INDEX(lists!L:L,RANDBETWEEN(1,3)) )} -> Pots & Pans | H13: =RANDBETWEEN(1,4) -> 2 | I13: =IF(C13<>"", RANDBETWEEN(1,H13), "") -> 2 | J13: {=INDEX(lists!A:A,RANDBETWEEN(1,19))} -> Center for Real Estate Studies | K13: {=INDEX(lists!N:N,RANDBETWEEN(1,6))} -> Scarborough | L13: =RANDBETWEEN(1,6) -> 2 | M13: {=INDEX(lists!O:O,RANDBETWEEN(1,2))} -> Pickup | N13: =RANDBETWEEN(1,6) -> 4
... A501: =ROW()-1 -> 500 | B501: =DATE(2024,1,1)+RANDBETWEEN(0,540) -> 45494 | C501: =IF(RAND()<=0.8, IF(RANDBETWEEN(1,10)<=8, B501+RANDBETWEEN(1,14), B501+RANDBETWEEN(15,45) ), "") -> 45506 | D501: =IF(C501<>"","Completed", IF(RAND()<=0.7,"Pending","Cancelled")) -> Completed | E501: =IF(C501<>"", C501-B501, "") -> 12 | F501: {=INDEX(lists!F:F,RANDBETWEEN(1,6))} -> Office | G501: {=IFS( F501="Bedroom",INDEX(lists!G:G,RANDBETWEEN(1,4)), F501="Living Room",INDEX(lists!H:H,RANDBETWEEN(1,4)), F501="Dining",INDEX(lists!I:I,RANDBETWEEN(1,2)), F501="Kitchen",INDEX(lists!J:J,RANDBETWEEN(1,4)), F501="Office",INDEX(lists!K:K,RANDBETWEEN(1,3)), F501="Household Essentials",INDEX(lists!L:L,RANDBETWEEN(1,3)) )} -> Desk | H501: =RANDBETWEEN(1,4) -> 4 | I501: =IF(C501<>"", RANDBETWEEN(1,H501), "") -> 1 | J501: {=INDEX(lists!A:A,RANDBETWEEN(1,19))} -> Portland Mattress Makers | K501: {=INDEX(lists!N:N,RANDBETWEEN(1,6))} -> Falmouth | L501: =RANDBETWEEN(1,6) -> 6 | M501: {=INDEX(lists!O:O,RANDBETWEEN(1,2))} -> Delivery | N501: =RANDBETWEEN(1,6) -> 2

Sheet lists
A1: Westbrook Housing | B1: Housing Authority | C1: Westbrook | D1: Southern ME | F1: Bedroom | G1: Bed Frame | H1: Sofa | I1: Dining Table | J1: Dishes | K1: Desk | L1: Bedding | N1: Westbrook | O1: Delivery
A2: Keybank | B2: Corporate Partner | C2: Portland | D2: Southern ME | F2: Living Room | G2: Mattress | H2: Armchair | I2: Dining Chair | J2: Pots & Pans | K2: Office Chair | L2: Lamps | N2: Portland | O2: Pickup
A3: Jordan's Furniture | B3: Corporate Donor | C3: Portland | D3: Southern ME | F3: Dining | G3: Dresser | H3: Coffee Table | J3: Microwave | K3: Bookshelf | L3: Rugs | N3: South Portland
A4: Diversified | B4: Corporate Partner | C4: Portland | D4: Southern ME | F4: Kitchen | G4: Nightstand | H4: TV Stand | J4: Small Appliances | N4: Scarborough
A5: Shutterbugs 4 Charity | B5: Nonprofit | C5: Portland | D5: Southern ME | F5: Office | N5: Falmouth
A6: Center for Real Estate Studies | B6: Education / Research | C6: Portland | D6: Southern ME | F6: Household Essentials | N6: Biddeford
A7: Portland Mattress Makers | B7: Manufacturer / Donor | C7: Portland | D7: Southern ME
A8: Developers Collaborative | B8: Corporate Partner | C8: Portland | D8: Southern ME
A9: Rowe Ford Westbrook | B9: Corporate Donor | C9: Westbrook | D9: Southern ME
A10: GoGo Refill | B10: Small Business Partner | C10: Portland | D10: Southern ME
A11: NewHeight Group | B11: Corporate Partner | C11: Portland | D11: Southern ME
A12: EthosVont | B12: Corporate Partner | C12: Portland | D12: Southern ME
A13: Maine Community Bank | B13: Financial Institution | C13: Biddeford | D13: Southern ME
A14: Portland Harbor Group Raymond James | B14: Financial Services | C14: Portland | D14: Southern ME
A15: Spiritual Workers | B15: Faith-Based Organization | C15: Portland | D15: Southern ME
A16: Saco & Biddeford Savings | B16: Financial Institution | C16: Biddeford | D16: Southern ME
A17: Coffee By Design | B17: Small Business Partner | C17: Portland | D17: Southern ME
A18: J.B Brown and Sons | B18: Construction / Trades | C18: South Portland | D18: Southern ME
A19: Systems Engineering | B19: Technology / Corporate Partner | C19: Portland | D19: Southern ME
